2023-06-04 19:45:29,152	[INFO]	/usr/local/lib/python3.11/site-packages/django/utils/autoreload.py(Line:668)	Watching for file changes with StatReloader
2023-06-04 19:46:29,755	[INFO]	/usr/local/lib/python3.11/site-packages/django/utils/autoreload.py(Line:668)	Watching for file changes with StatReloader
2023-06-04 19:46:54,648	[INFO]	/usr/local/lib/python3.11/site-packages/django/utils/autoreload.py(Line:668)	Watching for file changes with StatReloader
2023-06-04 19:47:00,025	[ERROR]	/usr/local/lib/python3.11/site-packages/django/utils/log.py(Line:241)	Internal Server Error: /
Traceback (most recent call last):
  File "/usr/local/lib/python3.11/site-packages/django/core/handlers/exception.py", line 55, in inner
    response = get_response(request)
               ^^^^^^^^^^^^^^^^^^^^^
  File "/usr/local/lib/python3.11/site-packages/django/core/handlers/base.py", line 197, in _get_response
    response = wrapped_callback(request, *callback_args, **callback_kwargs)
               ^^^^^^^^^^^^^^^^^^^^^^^^^^^^^^^^^^^^^^^^^^^^^^^^^^^^^^^^^^^^
  File "/usr/local/lib/python3.11/site-packages/django/views/generic/base.py", line 104, in view
    return self.dispatch(request, *args, **kwargs)
           ^^^^^^^^^^^^^^^^^^^^^^^^^^^^^^^^^^^^^^^
  File "/usr/local/lib/python3.11/site-packages/django/contrib/auth/mixins.py", line 132, in dispatch
    user_test_result = self.get_test_func()()
                       ^^^^^^^^^^^^^^^^^^^^^^
  File "/workspace/diary/views.py", line 21, in test_func
    diary = get_object_or_404(Diary, pk=self.kwargs["pk"])  # type: ignore
                                        ~~~~~~~~~~~^^^^^^
KeyError: 'pk'
2023-06-04 19:47:00,026	[ERROR]	/usr/local/lib/python3.11/site-packages/django/core/servers/basehttp.py(Line:212)	"GET / HTTP/1.1" 500 71687
2023-06-04 19:47:00,143	[WARNING]	/usr/local/lib/python3.11/site-packages/django/utils/log.py(Line:241)	Not Found: /favicon.ico
2023-06-04 19:47:00,143	[WARNING]	/usr/local/lib/python3.11/site-packages/django/core/servers/basehttp.py(Line:212)	"GET /favicon.ico HTTP/1.1" 404 3628
2023-06-04 19:47:52,315	[INFO]	/usr/local/lib/python3.11/site-packages/django/utils/autoreload.py(Line:266)	/workspace/diary/views.py changed, reloading.
2023-06-04 19:47:52,489	[INFO]	/usr/local/lib/python3.11/site-packages/django/utils/autoreload.py(Line:668)	Watching for file changes with StatReloader
2023-06-04 19:47:53,548	[INFO]	/usr/local/lib/python3.11/site-packages/django/utils/autoreload.py(Line:266)	/workspace/diary/views.py changed, reloading.
2023-06-04 19:47:53,710	[INFO]	/usr/local/lib/python3.11/site-packages/django/utils/autoreload.py(Line:668)	Watching for file changes with StatReloader
2023-06-04 19:47:55,822	[INFO]	/usr/local/lib/python3.11/site-packages/django/utils/autoreload.py(Line:266)	/workspace/diary/views.py changed, reloading.
2023-06-04 19:47:55,984	[INFO]	/usr/local/lib/python3.11/site-packages/django/utils/autoreload.py(Line:668)	Watching for file changes with StatReloader
2023-06-04 19:47:59,374	[ERROR]	/usr/local/lib/python3.11/site-packages/django/utils/log.py(Line:241)	Internal Server Error: /
Traceback (most recent call last):
  File "/usr/local/lib/python3.11/site-packages/django/core/handlers/exception.py", line 55, in inner
    response = get_response(request)
               ^^^^^^^^^^^^^^^^^^^^^
  File "/usr/local/lib/python3.11/site-packages/django/core/handlers/base.py", line 197, in _get_response
    response = wrapped_callback(request, *callback_args, **callback_kwargs)
               ^^^^^^^^^^^^^^^^^^^^^^^^^^^^^^^^^^^^^^^^^^^^^^^^^^^^^^^^^^^^
  File "/usr/local/lib/python3.11/site-packages/django/views/generic/base.py", line 104, in view
    return self.dispatch(request, *args, **kwargs)
           ^^^^^^^^^^^^^^^^^^^^^^^^^^^^^^^^^^^^^^^
  File "/usr/local/lib/python3.11/site-packages/django/contrib/auth/mixins.py", line 132, in dispatch
    user_test_result = self.get_test_func()()
                       ^^^^^^^^^^^^^^^^^^^^^^
  File "/workspace/diary/views.py", line 21, in test_func
    diary = get_object_or_404(Diary, pk=self.kwargs["pk"])  # type: ignore
                                        ~~~~~~~~~~~^^^^^^
KeyError: 'pk'
2023-06-04 19:47:59,374	[ERROR]	/usr/local/lib/python3.11/site-packages/django/core/servers/basehttp.py(Line:212)	"GET / HTTP/1.1" 500 71824
2023-06-04 19:49:54,246	[INFO]	/usr/local/lib/python3.11/site-packages/django/utils/autoreload.py(Line:668)	Watching for file changes with StatReloader
2023-06-04 19:50:00,912	[INFO]	/usr/local/lib/python3.11/site-packages/django/utils/autoreload.py(Line:668)	Watching for file changes with StatReloader
2023-06-04 19:50:05,503	[ERROR]	/usr/local/lib/python3.11/site-packages/django/utils/log.py(Line:241)	Internal Server Error: /
Traceback (most recent call last):
  File "/usr/local/lib/python3.11/site-packages/django/core/handlers/exception.py", line 55, in inner
    response = get_response(request)
               ^^^^^^^^^^^^^^^^^^^^^
  File "/usr/local/lib/python3.11/site-packages/django/core/handlers/base.py", line 197, in _get_response
    response = wrapped_callback(request, *callback_args, **callback_kwargs)
               ^^^^^^^^^^^^^^^^^^^^^^^^^^^^^^^^^^^^^^^^^^^^^^^^^^^^^^^^^^^^
  File "/usr/local/lib/python3.11/site-packages/django/views/generic/base.py", line 104, in view
    return self.dispatch(request, *args, **kwargs)
           ^^^^^^^^^^^^^^^^^^^^^^^^^^^^^^^^^^^^^^^
  File "/usr/local/lib/python3.11/site-packages/django/contrib/auth/mixins.py", line 132, in dispatch
    user_test_result = self.get_test_func()()
                       ^^^^^^^^^^^^^^^^^^^^^^
  File "/workspace/diary/views.py", line 21, in test_func
    diary = get_object_or_404(Diary, pk=self.kwargs["pk"])  # type: ignore
                                        ~~~~~~~~~~~^^^^^^
KeyError: 'pk'
2023-06-04 19:50:05,504	[ERROR]	/usr/local/lib/python3.11/site-packages/django/core/servers/basehttp.py(Line:212)	"GET / HTTP/1.1" 500 71800
2023-06-04 19:50:06,230	[ERROR]	/usr/local/lib/python3.11/site-packages/django/utils/log.py(Line:241)	Internal Server Error: /
Traceback (most recent call last):
  File "/usr/local/lib/python3.11/site-packages/django/core/handlers/exception.py", line 55, in inner
    response = get_response(request)
               ^^^^^^^^^^^^^^^^^^^^^
  File "/usr/local/lib/python3.11/site-packages/django/core/handlers/base.py", line 197, in _get_response
    response = wrapped_callback(request, *callback_args, **callback_kwargs)
               ^^^^^^^^^^^^^^^^^^^^^^^^^^^^^^^^^^^^^^^^^^^^^^^^^^^^^^^^^^^^
  File "/usr/local/lib/python3.11/site-packages/django/views/generic/base.py", line 104, in view
    return self.dispatch(request, *args, **kwargs)
           ^^^^^^^^^^^^^^^^^^^^^^^^^^^^^^^^^^^^^^^
  File "/usr/local/lib/python3.11/site-packages/django/contrib/auth/mixins.py", line 132, in dispatch
    user_test_result = self.get_test_func()()
                       ^^^^^^^^^^^^^^^^^^^^^^
  File "/workspace/diary/views.py", line 21, in test_func
    diary = get_object_or_404(Diary, pk=self.kwargs["pk"])  # type: ignore
                                        ~~~~~~~~~~~^^^^^^
KeyError: 'pk'
2023-06-04 19:50:06,231	[ERROR]	/usr/local/lib/python3.11/site-packages/django/core/servers/basehttp.py(Line:212)	"GET / HTTP/1.1" 500 71651
2023-06-04 19:50:20,611	[INFO]	/usr/local/lib/python3.11/site-packages/django/core/servers/basehttp.py(Line:212)	"GET /accounts/signup/ HTTP/1.1" 200 4261
2023-06-04 19:50:20,622	[INFO]	/usr/local/lib/python3.11/site-packages/django/core/servers/basehttp.py(Line:212)	"GET /static/css/mystyle.css HTTP/1.1" 304 0
2023-06-04 19:50:20,625	[WARNING]	/usr/local/lib/python3.11/site-packages/django/core/servers/basehttp.py(Line:212)	"GET /static/js/bootstrap.bundle.min.js HTTP/1.1" 404 1837
2023-06-04 19:50:20,626	[INFO]	/usr/local/lib/python3.11/site-packages/django/core/servers/basehttp.py(Line:212)	"GET /static/css/one-page-wonder.css HTTP/1.1" 200 239327
2023-06-04 19:50:27,238	[ERROR]	/usr/local/lib/python3.11/site-packages/django/utils/log.py(Line:241)	Internal Server Error: /
Traceback (most recent call last):
  File "/usr/local/lib/python3.11/site-packages/django/core/handlers/exception.py", line 55, in inner
    response = get_response(request)
               ^^^^^^^^^^^^^^^^^^^^^
  File "/usr/local/lib/python3.11/site-packages/django/core/handlers/base.py", line 197, in _get_response
    response = wrapped_callback(request, *callback_args, **callback_kwargs)
               ^^^^^^^^^^^^^^^^^^^^^^^^^^^^^^^^^^^^^^^^^^^^^^^^^^^^^^^^^^^^
  File "/usr/local/lib/python3.11/site-packages/django/views/generic/base.py", line 104, in view
    return self.dispatch(request, *args, **kwargs)
           ^^^^^^^^^^^^^^^^^^^^^^^^^^^^^^^^^^^^^^^
  File "/usr/local/lib/python3.11/site-packages/django/contrib/auth/mixins.py", line 132, in dispatch
    user_test_result = self.get_test_func()()
                       ^^^^^^^^^^^^^^^^^^^^^^
  File "/workspace/diary/views.py", line 21, in test_func
    diary = get_object_or_404(Diary, pk=self.kwargs["pk"])  # type: ignore
                                        ~~~~~~~~~~~^^^^^^
KeyError: 'pk'
2023-06-04 19:50:27,239	[ERROR]	/usr/local/lib/python3.11/site-packages/django/core/servers/basehttp.py(Line:212)	"GET / HTTP/1.1" 500 71681
2023-06-04 19:50:32,975	[ERROR]	/usr/local/lib/python3.11/site-packages/django/utils/log.py(Line:241)	Internal Server Error: /
Traceback (most recent call last):
  File "/usr/local/lib/python3.11/site-packages/django/core/handlers/exception.py", line 55, in inner
    response = get_response(request)
               ^^^^^^^^^^^^^^^^^^^^^
  File "/usr/local/lib/python3.11/site-packages/django/core/handlers/base.py", line 197, in _get_response
    response = wrapped_callback(request, *callback_args, **callback_kwargs)
               ^^^^^^^^^^^^^^^^^^^^^^^^^^^^^^^^^^^^^^^^^^^^^^^^^^^^^^^^^^^^
  File "/usr/local/lib/python3.11/site-packages/django/views/generic/base.py", line 104, in view
    return self.dispatch(request, *args, **kwargs)
           ^^^^^^^^^^^^^^^^^^^^^^^^^^^^^^^^^^^^^^^
  File "/usr/local/lib/python3.11/site-packages/django/contrib/auth/mixins.py", line 132, in dispatch
    user_test_result = self.get_test_func()()
                       ^^^^^^^^^^^^^^^^^^^^^^
  File "/workspace/diary/views.py", line 21, in test_func
    diary = get_object_or_404(Diary, pk=self.kwargs["pk"])  # type: ignore
                                        ~~~~~~~~~~~^^^^^^
KeyError: 'pk'
2023-06-04 19:50:32,976	[ERROR]	/usr/local/lib/python3.11/site-packages/django/core/servers/basehttp.py(Line:212)	"GET / HTTP/1.1" 500 71681
2023-06-04 19:50:43,151	[ERROR]	/usr/local/lib/python3.11/site-packages/django/utils/log.py(Line:241)	Internal Server Error: /inquiry
Traceback (most recent call last):
  File "/usr/local/lib/python3.11/site-packages/django/core/handlers/exception.py", line 55, in inner
    response = get_response(request)
               ^^^^^^^^^^^^^^^^^^^^^
  File "/usr/local/lib/python3.11/site-packages/django/core/handlers/base.py", line 197, in _get_response
    response = wrapped_callback(request, *callback_args, **callback_kwargs)
               ^^^^^^^^^^^^^^^^^^^^^^^^^^^^^^^^^^^^^^^^^^^^^^^^^^^^^^^^^^^^
  File "/usr/local/lib/python3.11/site-packages/django/views/generic/base.py", line 104, in view
    return self.dispatch(request, *args, **kwargs)
           ^^^^^^^^^^^^^^^^^^^^^^^^^^^^^^^^^^^^^^^
  File "/usr/local/lib/python3.11/site-packages/django/contrib/auth/mixins.py", line 132, in dispatch
    user_test_result = self.get_test_func()()
                       ^^^^^^^^^^^^^^^^^^^^^^
  File "/workspace/diary/views.py", line 21, in test_func
    diary = get_object_or_404(Diary, pk=self.kwargs["pk"])  # type: ignore
                                        ~~~~~~~~~~~^^^^^^
KeyError: 'pk'
2023-06-04 19:50:43,151	[ERROR]	/usr/local/lib/python3.11/site-packages/django/core/servers/basehttp.py(Line:212)	"GET /inquiry HTTP/1.1" 500 71768
2023-06-04 19:50:48,025	[INFO]	/usr/local/lib/python3.11/site-packages/django/core/servers/basehttp.py(Line:212)	"GET /accounts/login/ HTTP/1.1" 200 4347
2023-06-04 19:50:48,035	[WARNING]	/usr/local/lib/python3.11/site-packages/django/core/servers/basehttp.py(Line:212)	"GET /static/js/bootstrap.bundle.min.js HTTP/1.1" 404 1837
2023-06-04 19:50:57,237	[INFO]	/usr/local/lib/python3.11/site-packages/django/core/servers/basehttp.py(Line:212)	"POST /accounts/login/ HTTP/1.1" 200 4574
2023-06-04 19:50:57,246	[WARNING]	/usr/local/lib/python3.11/site-packages/django/core/servers/basehttp.py(Line:212)	"GET /static/js/bootstrap.bundle.min.js HTTP/1.1" 404 1837
2023-06-04 19:51:08,402	[INFO]	/usr/local/lib/python3.11/site-packages/django/core/servers/basehttp.py(Line:212)	"POST /accounts/login/ HTTP/1.1" 200 4563
2023-06-04 19:51:08,420	[WARNING]	/usr/local/lib/python3.11/site-packages/django/core/servers/basehttp.py(Line:212)	"GET /static/js/bootstrap.bundle.min.js HTTP/1.1" 404 1837
2023-06-04 19:51:12,925	[INFO]	/usr/local/lib/python3.11/site-packages/django/core/servers/basehttp.py(Line:212)	"GET /accounts/signup/ HTTP/1.1" 200 4261
2023-06-04 19:51:12,943	[WARNING]	/usr/local/lib/python3.11/site-packages/django/core/servers/basehttp.py(Line:212)	"GET /static/js/bootstrap.bundle.min.js HTTP/1.1" 404 1837
2023-06-04 19:51:27,607	[INFO]	/usr/local/lib/python3.11/site-packages/django/core/servers/basehttp.py(Line:212)	"POST /accounts/signup/ HTTP/1.1" 302 0
2023-06-04 19:51:27,615	[INFO]	/usr/local/lib/python3.11/site-packages/django/core/servers/basehttp.py(Line:212)	"GET /accounts/confirm-email/ HTTP/1.1" 200 3911
2023-06-04 19:51:27,626	[WARNING]	/usr/local/lib/python3.11/site-packages/django/core/servers/basehttp.py(Line:212)	"GET /static/js/bootstrap.bundle.min.js HTTP/1.1" 404 1837
2023-06-04 19:51:35,434	[INFO]	/usr/local/lib/python3.11/site-packages/django/core/servers/basehttp.py(Line:212)	"GET /accounts/confirm-email/MQ:1q5lKZ:zga5KeIgmFsq8AxQedqCOljBFLVWrdyCjWtBPn9vAFw/ HTTP/1.1" 200 3624
2023-06-04 19:51:35,448	[WARNING]	/usr/local/lib/python3.11/site-packages/django/core/servers/basehttp.py(Line:212)	"GET /static/js/bootstrap.bundle.min.js HTTP/1.1" 404 1837
2023-06-04 19:51:37,453	[INFO]	/usr/local/lib/python3.11/site-packages/django/core/servers/basehttp.py(Line:212)	"POST /accounts/confirm-email/MQ:1q5lKh:dd52d10DIhXCY7oVsxLeQWdC72MR_SbmOTbgsVz6cfo/ HTTP/1.1" 302 0
2023-06-04 19:51:37,461	[INFO]	/usr/local/lib/python3.11/site-packages/django/core/servers/basehttp.py(Line:212)	"GET /accounts/login/ HTTP/1.1" 200 4754
2023-06-04 19:51:37,470	[WARNING]	/usr/local/lib/python3.11/site-packages/django/core/servers/basehttp.py(Line:212)	"GET /static/js/bootstrap.bundle.min.js HTTP/1.1" 404 1837
2023-06-04 19:51:45,901	[INFO]	/usr/local/lib/python3.11/site-packages/django/core/servers/basehttp.py(Line:212)	"POST /accounts/login/ HTTP/1.1" 302 0
2023-06-04 19:51:45,916	[ERROR]	/usr/local/lib/python3.11/site-packages/django/utils/log.py(Line:241)	Internal Server Error: /diary-list
Traceback (most recent call last):
  File "/usr/local/lib/python3.11/site-packages/django/core/handlers/exception.py", line 55, in inner
    response = get_response(request)
               ^^^^^^^^^^^^^^^^^^^^^
  File "/usr/local/lib/python3.11/site-packages/django/core/handlers/base.py", line 197, in _get_response
    response = wrapped_callback(request, *callback_args, **callback_kwargs)
               ^^^^^^^^^^^^^^^^^^^^^^^^^^^^^^^^^^^^^^^^^^^^^^^^^^^^^^^^^^^^
  File "/usr/local/lib/python3.11/site-packages/django/views/generic/base.py", line 104, in view
    return self.dispatch(request, *args, **kwargs)
           ^^^^^^^^^^^^^^^^^^^^^^^^^^^^^^^^^^^^^^^
  File "/usr/local/lib/python3.11/site-packages/django/contrib/auth/mixins.py", line 73, in dispatch
    return super().dispatch(request, *args, **kwargs)
           ^^^^^^^^^^^^^^^^^^^^^^^^^^^^^^^^^^^^^^^^^^
  File "/usr/local/lib/python3.11/site-packages/django/contrib/auth/mixins.py", line 132, in dispatch
    user_test_result = self.get_test_func()()
                       ^^^^^^^^^^^^^^^^^^^^^^
  File "/workspace/diary/views.py", line 21, in test_func
    diary = get_object_or_404(Diary, pk=self.kwargs["pk"])  # type: ignore
                                        ~~~~~~~~~~~^^^^^^
KeyError: 'pk'
2023-06-04 19:51:45,916	[ERROR]	/usr/local/lib/python3.11/site-packages/django/core/servers/basehttp.py(Line:212)	"GET /diary-list HTTP/1.1" 500 76898
2023-06-04 19:52:26,139	[INFO]	/usr/local/lib/python3.11/site-packages/django/utils/autoreload.py(Line:266)	/workspace/diary/views.py changed, reloading.
2023-06-04 19:52:26,329	[INFO]	/usr/local/lib/python3.11/site-packages/django/utils/autoreload.py(Line:668)	Watching for file changes with StatReloader
2023-06-04 19:52:28,096	[ERROR]	/usr/local/lib/python3.11/site-packages/django/utils/log.py(Line:241)	Internal Server Error: /diary-list
Traceback (most recent call last):
  File "/usr/local/lib/python3.11/site-packages/django/core/handlers/exception.py", line 55, in inner
    response = get_response(request)
               ^^^^^^^^^^^^^^^^^^^^^
  File "/usr/local/lib/python3.11/site-packages/django/core/handlers/base.py", line 197, in _get_response
    response = wrapped_callback(request, *callback_args, **callback_kwargs)
               ^^^^^^^^^^^^^^^^^^^^^^^^^^^^^^^^^^^^^^^^^^^^^^^^^^^^^^^^^^^^
  File "/usr/local/lib/python3.11/site-packages/django/views/generic/base.py", line 104, in view
    return self.dispatch(request, *args, **kwargs)
           ^^^^^^^^^^^^^^^^^^^^^^^^^^^^^^^^^^^^^^^
  File "/usr/local/lib/python3.11/site-packages/django/contrib/auth/mixins.py", line 73, in dispatch
    return super().dispatch(request, *args, **kwargs)
           ^^^^^^^^^^^^^^^^^^^^^^^^^^^^^^^^^^^^^^^^^^
  File "/usr/local/lib/python3.11/site-packages/django/contrib/auth/mixins.py", line 132, in dispatch
    user_test_result = self.get_test_func()()
                       ^^^^^^^^^^^^^^^^^^^^^^
  File "/workspace/diary/views.py", line 21, in test_func
    diary = get_object_or_404(Diary, pk=self.kwargs['pk'])  # type: ignore
                                        ~~~~~~~~~~~^^^^^^
KeyError: 'pk'
2023-06-04 19:52:28,096	[ERROR]	/usr/local/lib/python3.11/site-packages/django/core/servers/basehttp.py(Line:212)	"GET /diary-list HTTP/1.1" 500 76898
2023-06-04 19:52:36,498	[WARNING]	/usr/local/lib/python3.11/site-packages/django/utils/log.py(Line:241)	Forbidden (CSRF token from POST incorrect.): /accounts/login/
2023-06-04 19:52:36,498	[WARNING]	/usr/local/lib/python3.11/site-packages/django/core/servers/basehttp.py(Line:212)	"POST /accounts/login/ HTTP/1.1" 403 2561
2023-06-04 19:52:43,772	[WARNING]	/usr/local/lib/python3.11/site-packages/django/utils/log.py(Line:241)	Forbidden (CSRF token from POST incorrect.): /accounts/login/
2023-06-04 19:52:43,772	[WARNING]	/usr/local/lib/python3.11/site-packages/django/core/servers/basehttp.py(Line:212)	"POST /accounts/login/ HTTP/1.1" 403 2561
2023-06-04 19:52:44,972	[INFO]	/usr/local/lib/python3.11/site-packages/django/core/servers/basehttp.py(Line:212)	"GET /accounts/login/ HTTP/1.1" 302 0
2023-06-04 19:52:47,222	[INFO]	/usr/local/lib/python3.11/site-packages/django/core/servers/basehttp.py(Line:212)	"GET /accounts/logout/ HTTP/1.1" 302 0
2023-06-04 19:52:47,235	[INFO]	/usr/local/lib/python3.11/site-packages/django/core/servers/basehttp.py(Line:212)	"GET /accounts/login/ HTTP/1.1" 200 4936
2023-06-04 19:52:47,246	[WARNING]	/usr/local/lib/python3.11/site-packages/django/core/servers/basehttp.py(Line:212)	"GET /static/js/bootstrap.bundle.min.js HTTP/1.1" 404 1837
2023-06-04 19:52:51,484	[INFO]	/usr/local/lib/python3.11/site-packages/django/core/servers/basehttp.py(Line:212)	"GET /accounts/signup/ HTTP/1.1" 200 4261
2023-06-04 19:52:51,493	[WARNING]	/usr/local/lib/python3.11/site-packages/django/core/servers/basehttp.py(Line:212)	"GET /static/js/bootstrap.bundle.min.js HTTP/1.1" 404 1837
2023-06-04 19:52:52,159	[INFO]	/usr/local/lib/python3.11/site-packages/django/core/servers/basehttp.py(Line:212)	"GET /accounts/login/ HTTP/1.1" 200 4347
2023-06-04 19:52:52,176	[WARNING]	/usr/local/lib/python3.11/site-packages/django/core/servers/basehttp.py(Line:212)	"GET /static/js/bootstrap.bundle.min.js HTTP/1.1" 404 1837
2023-06-04 19:52:58,789	[INFO]	/usr/local/lib/python3.11/site-packages/django/core/servers/basehttp.py(Line:212)	"POST /accounts/login/ HTTP/1.1" 302 0
2023-06-04 19:52:58,806	[ERROR]	/usr/local/lib/python3.11/site-packages/django/utils/log.py(Line:241)	Internal Server Error: /diary-list
Traceback (most recent call last):
  File "/usr/local/lib/python3.11/site-packages/django/core/handlers/exception.py", line 55, in inner
    response = get_response(request)
               ^^^^^^^^^^^^^^^^^^^^^
  File "/usr/local/lib/python3.11/site-packages/django/core/handlers/base.py", line 197, in _get_response
    response = wrapped_callback(request, *callback_args, **callback_kwargs)
               ^^^^^^^^^^^^^^^^^^^^^^^^^^^^^^^^^^^^^^^^^^^^^^^^^^^^^^^^^^^^
  File "/usr/local/lib/python3.11/site-packages/django/views/generic/base.py", line 104, in view
    return self.dispatch(request, *args, **kwargs)
           ^^^^^^^^^^^^^^^^^^^^^^^^^^^^^^^^^^^^^^^
  File "/usr/local/lib/python3.11/site-packages/django/contrib/auth/mixins.py", line 73, in dispatch
    return super().dispatch(request, *args, **kwargs)
           ^^^^^^^^^^^^^^^^^^^^^^^^^^^^^^^^^^^^^^^^^^
  File "/usr/local/lib/python3.11/site-packages/django/contrib/auth/mixins.py", line 132, in dispatch
    user_test_result = self.get_test_func()()
                       ^^^^^^^^^^^^^^^^^^^^^^
  File "/workspace/diary/views.py", line 21, in test_func
    diary = get_object_or_404(Diary, pk=self.kwargs['pk'])  # type: ignore
                                        ~~~~~~~~~~~^^^^^^
KeyError: 'pk'
2023-06-04 19:52:58,807	[ERROR]	/usr/local/lib/python3.11/site-packages/django/core/servers/basehttp.py(Line:212)	"GET /diary-list HTTP/1.1" 500 76898
2023-06-04 19:53:45,182	[INFO]	/usr/local/lib/python3.11/site-packages/django/utils/autoreload.py(Line:266)	/workspace/diary/views.py changed, reloading.
2023-06-04 19:53:45,356	[INFO]	/usr/local/lib/python3.11/site-packages/django/utils/autoreload.py(Line:668)	Watching for file changes with StatReloader
2023-06-04 19:53:47,473	[INFO]	/usr/local/lib/python3.11/site-packages/django/utils/autoreload.py(Line:266)	/workspace/diary/views.py changed, reloading.
2023-06-04 19:53:47,637	[INFO]	/usr/local/lib/python3.11/site-packages/django/utils/autoreload.py(Line:668)	Watching for file changes with StatReloader
2023-06-04 19:53:49,009	[ERROR]	/usr/local/lib/python3.11/site-packages/django/utils/log.py(Line:241)	Internal Server Error: /diary-list
Traceback (most recent call last):
  File "/usr/local/lib/python3.11/site-packages/django/core/handlers/exception.py", line 55, in inner
    response = get_response(request)
               ^^^^^^^^^^^^^^^^^^^^^
  File "/usr/local/lib/python3.11/site-packages/django/core/handlers/base.py", line 197, in _get_response
    response = wrapped_callback(request, *callback_args, **callback_kwargs)
               ^^^^^^^^^^^^^^^^^^^^^^^^^^^^^^^^^^^^^^^^^^^^^^^^^^^^^^^^^^^^
  File "/usr/local/lib/python3.11/site-packages/django/views/generic/base.py", line 104, in view
    return self.dispatch(request, *args, **kwargs)
           ^^^^^^^^^^^^^^^^^^^^^^^^^^^^^^^^^^^^^^^
  File "/usr/local/lib/python3.11/site-packages/django/contrib/auth/mixins.py", line 73, in dispatch
    return super().dispatch(request, *args, **kwargs)
           ^^^^^^^^^^^^^^^^^^^^^^^^^^^^^^^^^^^^^^^^^^
  File "/usr/local/lib/python3.11/site-packages/django/contrib/auth/mixins.py", line 132, in dispatch
    user_test_result = self.get_test_func()()
                       ^^^^^^^^^^^^^^^^^^^^^^
  File "/workspace/diary/views.py", line 21, in test_func
    diary = get_object_or_404(Diary, pk=self.kwargs['pk'])  # type: ignore
                                        ~~~~~~~~~~~^^^^^^
KeyError: 'pk'
2023-06-04 19:53:49,010	[ERROR]	/usr/local/lib/python3.11/site-packages/django/core/servers/basehttp.py(Line:212)	"GET /diary-list HTTP/1.1" 500 76903
2023-06-04 19:55:24,539	[INFO]	/usr/local/lib/python3.11/site-packages/django/utils/autoreload.py(Line:266)	/workspace/diary/views.py changed, reloading.
2023-06-04 19:55:24,705	[INFO]	/usr/local/lib/python3.11/site-packages/django/utils/autoreload.py(Line:668)	Watching for file changes with StatReloader
2023-06-04 19:55:29,834	[INFO]	/usr/local/lib/python3.11/site-packages/django/utils/autoreload.py(Line:266)	/workspace/diary/views.py changed, reloading.
2023-06-04 19:55:30,009	[INFO]	/usr/local/lib/python3.11/site-packages/django/utils/autoreload.py(Line:668)	Watching for file changes with StatReloader
2023-06-04 19:55:35,395	[ERROR]	/usr/local/lib/python3.11/site-packages/django/utils/log.py(Line:241)	Internal Server Error: /diary-list
Traceback (most recent call last):
  File "/usr/local/lib/python3.11/site-packages/django/core/handlers/exception.py", line 55, in inner
    response = get_response(request)
               ^^^^^^^^^^^^^^^^^^^^^
  File "/usr/local/lib/python3.11/site-packages/django/core/handlers/base.py", line 197, in _get_response
    response = wrapped_callback(request, *callback_args, **callback_kwargs)
               ^^^^^^^^^^^^^^^^^^^^^^^^^^^^^^^^^^^^^^^^^^^^^^^^^^^^^^^^^^^^
  File "/usr/local/lib/python3.11/site-packages/django/views/generic/base.py", line 104, in view
    return self.dispatch(request, *args, **kwargs)
           ^^^^^^^^^^^^^^^^^^^^^^^^^^^^^^^^^^^^^^^
  File "/usr/local/lib/python3.11/site-packages/django/contrib/auth/mixins.py", line 132, in dispatch
    user_test_result = self.get_test_func()()
                       ^^^^^^^^^^^^^^^^^^^^^^
  File "/workspace/diary/views.py", line 21, in test_func
    diary = get_object_or_404(Diary, pk=self.kwargs['pk'])  # type: ignore
                                        ~~~~~~~~~~~^^^^^^
KeyError: 'pk'
2023-06-04 19:55:35,396	[ERROR]	/usr/local/lib/python3.11/site-packages/django/core/servers/basehttp.py(Line:212)	"GET /diary-list HTTP/1.1" 500 72380
2023-06-04 19:55:40,573	[INFO]	/usr/local/lib/python3.11/site-packages/django/core/servers/basehttp.py(Line:212)	"GET / HTTP/1.1" 200 5999
2023-06-04 19:55:40,588	[INFO]	/usr/local/lib/python3.11/site-packages/django/core/servers/basehttp.py(Line:212)	"GET /static/assets/img/02.jpg HTTP/1.1" 200 252376
2023-06-04 19:55:40,589	[INFO]	/usr/local/lib/python3.11/site-packages/django/core/servers/basehttp.py(Line:212)	"GET /static/assets/img/01.jpg HTTP/1.1" 200 547797
2023-06-04 19:55:40,600	[WARNING]	/usr/local/lib/python3.11/site-packages/django/core/servers/basehttp.py(Line:212)	"GET /static/js/bootstrap.bundle.min.js HTTP/1.1" 404 1837
2023-06-04 19:55:40,602	[INFO]	/usr/local/lib/python3.11/site-packages/django/core/servers/basehttp.py(Line:212)	"GET /static/assets/img/03.jpg HTTP/1.1" 200 535000
2023-06-04 19:55:44,873	[INFO]	/usr/local/lib/python3.11/site-packages/django/core/servers/basehttp.py(Line:212)	"GET /accounts/login/ HTTP/1.1" 302 0
2023-06-04 19:55:44,936	[ERROR]	/usr/local/lib/python3.11/site-packages/django/utils/log.py(Line:241)	Internal Server Error: /diary-list
Traceback (most recent call last):
  File "/usr/local/lib/python3.11/site-packages/django/core/handlers/exception.py", line 55, in inner
    response = get_response(request)
               ^^^^^^^^^^^^^^^^^^^^^
  File "/usr/local/lib/python3.11/site-packages/django/core/handlers/base.py", line 197, in _get_response
    response = wrapped_callback(request, *callback_args, **callback_kwargs)
               ^^^^^^^^^^^^^^^^^^^^^^^^^^^^^^^^^^^^^^^^^^^^^^^^^^^^^^^^^^^^
  File "/usr/local/lib/python3.11/site-packages/django/views/generic/base.py", line 104, in view
    return self.dispatch(request, *args, **kwargs)
           ^^^^^^^^^^^^^^^^^^^^^^^^^^^^^^^^^^^^^^^
  File "/usr/local/lib/python3.11/site-packages/django/contrib/auth/mixins.py", line 132, in dispatch
    user_test_result = self.get_test_func()()
                       ^^^^^^^^^^^^^^^^^^^^^^
  File "/workspace/diary/views.py", line 21, in test_func
    diary = get_object_or_404(Diary, pk=self.kwargs['pk'])  # type: ignore
                                        ~~~~~~~~~~~^^^^^^
KeyError: 'pk'
2023-06-04 19:55:44,936	[ERROR]	/usr/local/lib/python3.11/site-packages/django/core/servers/basehttp.py(Line:212)	"GET /diary-list HTTP/1.1" 500 71926
2023-06-04 19:56:09,525	[INFO]	/usr/local/lib/python3.11/site-packages/django/core/servers/basehttp.py(Line:212)	"GET /accounts/login/ HTTP/1.1" 302 0
2023-06-04 19:56:09,583	[ERROR]	/usr/local/lib/python3.11/site-packages/django/utils/log.py(Line:241)	Internal Server Error: /diary-list
Traceback (most recent call last):
  File "/usr/local/lib/python3.11/site-packages/django/core/handlers/exception.py", line 55, in inner
    response = get_response(request)
               ^^^^^^^^^^^^^^^^^^^^^
  File "/usr/local/lib/python3.11/site-packages/django/core/handlers/base.py", line 197, in _get_response
    response = wrapped_callback(request, *callback_args, **callback_kwargs)
               ^^^^^^^^^^^^^^^^^^^^^^^^^^^^^^^^^^^^^^^^^^^^^^^^^^^^^^^^^^^^
  File "/usr/local/lib/python3.11/site-packages/django/views/generic/base.py", line 104, in view
    return self.dispatch(request, *args, **kwargs)
           ^^^^^^^^^^^^^^^^^^^^^^^^^^^^^^^^^^^^^^^
  File "/usr/local/lib/python3.11/site-packages/django/contrib/auth/mixins.py", line 132, in dispatch
    user_test_result = self.get_test_func()()
                       ^^^^^^^^^^^^^^^^^^^^^^
  File "/workspace/diary/views.py", line 21, in test_func
    diary = get_object_or_404(Diary, pk=self.kwargs['pk'])  # type: ignore
                                        ~~~~~~~~~~~^^^^^^
KeyError: 'pk'
2023-06-04 19:56:09,583	[ERROR]	/usr/local/lib/python3.11/site-packages/django/core/servers/basehttp.py(Line:212)	"GET /diary-list HTTP/1.1" 500 71926
2023-06-04 19:56:12,006	[INFO]	/usr/local/lib/python3.11/site-packages/django/core/servers/basehttp.py(Line:212)	"GET /accounts/signup/ HTTP/1.1" 302 0
2023-06-04 19:56:12,065	[ERROR]	/usr/local/lib/python3.11/site-packages/django/utils/log.py(Line:241)	Internal Server Error: /diary-list
Traceback (most recent call last):
  File "/usr/local/lib/python3.11/site-packages/django/core/handlers/exception.py", line 55, in inner
    response = get_response(request)
               ^^^^^^^^^^^^^^^^^^^^^
  File "/usr/local/lib/python3.11/site-packages/django/core/handlers/base.py", line 197, in _get_response
    response = wrapped_callback(request, *callback_args, **callback_kwargs)
               ^^^^^^^^^^^^^^^^^^^^^^^^^^^^^^^^^^^^^^^^^^^^^^^^^^^^^^^^^^^^
  File "/usr/local/lib/python3.11/site-packages/django/views/generic/base.py", line 104, in view
    return self.dispatch(request, *args, **kwargs)
           ^^^^^^^^^^^^^^^^^^^^^^^^^^^^^^^^^^^^^^^
  File "/usr/local/lib/python3.11/site-packages/django/contrib/auth/mixins.py", line 132, in dispatch
    user_test_result = self.get_test_func()()
                       ^^^^^^^^^^^^^^^^^^^^^^
  File "/workspace/diary/views.py", line 21, in test_func
    diary = get_object_or_404(Diary, pk=self.kwargs['pk'])  # type: ignore
                                        ~~~~~~~~~~~^^^^^^
KeyError: 'pk'
2023-06-04 19:56:12,065	[ERROR]	/usr/local/lib/python3.11/site-packages/django/core/servers/basehttp.py(Line:212)	"GET /diary-list HTTP/1.1" 500 71926
2023-06-04 19:56:14,506	[INFO]	/usr/local/lib/python3.11/site-packages/django/core/servers/basehttp.py(Line:212)	"GET /accounts/login/ HTTP/1.1" 302 0
2023-06-04 19:56:14,568	[ERROR]	/usr/local/lib/python3.11/site-packages/django/utils/log.py(Line:241)	Internal Server Error: /diary-list
Traceback (most recent call last):
  File "/usr/local/lib/python3.11/site-packages/django/core/handlers/exception.py", line 55, in inner
    response = get_response(request)
               ^^^^^^^^^^^^^^^^^^^^^
  File "/usr/local/lib/python3.11/site-packages/django/core/handlers/base.py", line 197, in _get_response
    response = wrapped_callback(request, *callback_args, **callback_kwargs)
               ^^^^^^^^^^^^^^^^^^^^^^^^^^^^^^^^^^^^^^^^^^^^^^^^^^^^^^^^^^^^
  File "/usr/local/lib/python3.11/site-packages/django/views/generic/base.py", line 104, in view
    return self.dispatch(request, *args, **kwargs)
           ^^^^^^^^^^^^^^^^^^^^^^^^^^^^^^^^^^^^^^^
  File "/usr/local/lib/python3.11/site-packages/django/contrib/auth/mixins.py", line 132, in dispatch
    user_test_result = self.get_test_func()()
                       ^^^^^^^^^^^^^^^^^^^^^^
  File "/workspace/diary/views.py", line 21, in test_func
    diary = get_object_or_404(Diary, pk=self.kwargs['pk'])  # type: ignore
                                        ~~~~~~~~~~~^^^^^^
KeyError: 'pk'
2023-06-04 19:56:14,569	[ERROR]	/usr/local/lib/python3.11/site-packages/django/core/servers/basehttp.py(Line:212)	"GET /diary-list HTTP/1.1" 500 71926
2023-06-04 19:56:49,885	[INFO]	/usr/local/lib/python3.11/site-packages/django/utils/autoreload.py(Line:266)	/workspace/diary/views.py changed, reloading.
2023-06-04 19:56:50,066	[INFO]	/usr/local/lib/python3.11/site-packages/django/utils/autoreload.py(Line:668)	Watching for file changes with StatReloader
2023-06-04 19:57:07,315	[INFO]	/usr/local/lib/python3.11/site-packages/django/utils/autoreload.py(Line:266)	/workspace/diary/views.py changed, reloading.
2023-06-04 19:57:07,497	[INFO]	/usr/local/lib/python3.11/site-packages/django/utils/autoreload.py(Line:668)	Watching for file changes with StatReloader
2023-06-04 19:57:08,593	[INFO]	/usr/local/lib/python3.11/site-packages/django/utils/autoreload.py(Line:266)	/workspace/diary/views.py changed, reloading.
2023-06-04 19:57:08,757	[INFO]	/usr/local/lib/python3.11/site-packages/django/utils/autoreload.py(Line:668)	Watching for file changes with StatReloader
2023-06-04 19:57:09,422	[ERROR]	/usr/local/lib/python3.11/site-packages/django/utils/log.py(Line:241)	Internal Server Error: /
Traceback (most recent call last):
  File "/usr/local/lib/python3.11/site-packages/django/core/handlers/exception.py", line 55, in inner
    response = get_response(request)
               ^^^^^^^^^^^^^^^^^^^^^
  File "/usr/local/lib/python3.11/site-packages/django/core/handlers/base.py", line 197, in _get_response
    response = wrapped_callback(request, *callback_args, **callback_kwargs)
               ^^^^^^^^^^^^^^^^^^^^^^^^^^^^^^^^^^^^^^^^^^^^^^^^^^^^^^^^^^^^
  File "/usr/local/lib/python3.11/site-packages/django/views/generic/base.py", line 104, in view
    return self.dispatch(request, *args, **kwargs)
           ^^^^^^^^^^^^^^^^^^^^^^^^^^^^^^^^^^^^^^^
  File "/usr/local/lib/python3.11/site-packages/django/contrib/auth/mixins.py", line 132, in dispatch
    user_test_result = self.get_test_func()()
                       ^^^^^^^^^^^^^^^^^^^^^^
  File "/workspace/diary/views.py", line 21, in test_func
    diary = get_object_or_404(Diary, pk=self.kwargs['pk'])  # type: ignore
                                        ~~~~~~~~~~~^^^^^^
KeyError: 'pk'
2023-06-04 19:57:09,423	[ERROR]	/usr/local/lib/python3.11/site-packages/django/core/servers/basehttp.py(Line:212)	"GET / HTTP/1.1" 500 71796
2023-06-04 19:57:10,718	[ERROR]	/usr/local/lib/python3.11/site-packages/django/utils/log.py(Line:241)	Internal Server Error: /
Traceback (most recent call last):
  File "/usr/local/lib/python3.11/site-packages/django/core/handlers/exception.py", line 55, in inner
    response = get_response(request)
               ^^^^^^^^^^^^^^^^^^^^^
  File "/usr/local/lib/python3.11/site-packages/django/core/handlers/base.py", line 197, in _get_response
    response = wrapped_callback(request, *callback_args, **callback_kwargs)
               ^^^^^^^^^^^^^^^^^^^^^^^^^^^^^^^^^^^^^^^^^^^^^^^^^^^^^^^^^^^^
  File "/usr/local/lib/python3.11/site-packages/django/views/generic/base.py", line 104, in view
    return self.dispatch(request, *args, **kwargs)
           ^^^^^^^^^^^^^^^^^^^^^^^^^^^^^^^^^^^^^^^
  File "/usr/local/lib/python3.11/site-packages/django/contrib/auth/mixins.py", line 132, in dispatch
    user_test_result = self.get_test_func()()
                       ^^^^^^^^^^^^^^^^^^^^^^
  File "/workspace/diary/views.py", line 21, in test_func
    diary = get_object_or_404(Diary, pk=self.kwargs['pk'])  # type: ignore
                                        ~~~~~~~~~~~^^^^^^
KeyError: 'pk'
2023-06-04 19:57:10,719	[ERROR]	/usr/local/lib/python3.11/site-packages/django/core/servers/basehttp.py(Line:212)	"GET / HTTP/1.1" 500 71796
2023-06-04 19:57:11,197	[ERROR]	/usr/local/lib/python3.11/site-packages/django/utils/log.py(Line:241)	Internal Server Error: /
Traceback (most recent call last):
  File "/usr/local/lib/python3.11/site-packages/django/core/handlers/exception.py", line 55, in inner
    response = get_response(request)
               ^^^^^^^^^^^^^^^^^^^^^
  File "/usr/local/lib/python3.11/site-packages/django/core/handlers/base.py", line 197, in _get_response
    response = wrapped_callback(request, *callback_args, **callback_kwargs)
               ^^^^^^^^^^^^^^^^^^^^^^^^^^^^^^^^^^^^^^^^^^^^^^^^^^^^^^^^^^^^
  File "/usr/local/lib/python3.11/site-packages/django/views/generic/base.py", line 104, in view
    return self.dispatch(request, *args, **kwargs)
           ^^^^^^^^^^^^^^^^^^^^^^^^^^^^^^^^^^^^^^^
  File "/usr/local/lib/python3.11/site-packages/django/contrib/auth/mixins.py", line 132, in dispatch
    user_test_result = self.get_test_func()()
                       ^^^^^^^^^^^^^^^^^^^^^^
  File "/workspace/diary/views.py", line 21, in test_func
    diary = get_object_or_404(Diary, pk=self.kwargs['pk'])  # type: ignore
                                        ~~~~~~~~~~~^^^^^^
KeyError: 'pk'
2023-06-04 19:57:11,198	[ERROR]	/usr/local/lib/python3.11/site-packages/django/core/servers/basehttp.py(Line:212)	"GET / HTTP/1.1" 500 71796
2023-06-04 19:59:29,947	[INFO]	/usr/local/lib/python3.11/site-packages/django/utils/autoreload.py(Line:266)	/workspace/diary/views.py changed, reloading.
2023-06-04 19:59:30,114	[INFO]	/usr/local/lib/python3.11/site-packages/django/utils/autoreload.py(Line:668)	Watching for file changes with StatReloader
2023-06-04 19:59:36,201	[INFO]	/usr/local/lib/python3.11/site-packages/django/utils/autoreload.py(Line:266)	/workspace/diary/views.py changed, reloading.
2023-06-04 19:59:36,368	[INFO]	/usr/local/lib/python3.11/site-packages/django/utils/autoreload.py(Line:668)	Watching for file changes with StatReloader
2023-06-04 19:59:40,478	[INFO]	/usr/local/lib/python3.11/site-packages/django/utils/autoreload.py(Line:266)	/workspace/diary/views.py changed, reloading.
2023-06-04 19:59:40,655	[INFO]	/usr/local/lib/python3.11/site-packages/django/utils/autoreload.py(Line:668)	Watching for file changes with StatReloader
2023-06-04 19:59:41,703	[INFO]	/usr/local/lib/python3.11/site-packages/django/utils/autoreload.py(Line:266)	/workspace/diary/views.py changed, reloading.
2023-06-04 19:59:41,869	[INFO]	/usr/local/lib/python3.11/site-packages/django/utils/autoreload.py(Line:668)	Watching for file changes with StatReloader
2023-06-04 19:59:50,551	[INFO]	/usr/local/lib/python3.11/site-packages/django/core/servers/basehttp.py(Line:212)	"GET /accounts/confirm-email/ HTTP/1.1" 200 3698
2023-06-04 19:59:50,560	[WARNING]	/usr/local/lib/python3.11/site-packages/django/core/servers/basehttp.py(Line:212)	"GET /static/js/bootstrap.bundle.min.js HTTP/1.1" 404 1837
2023-06-04 19:59:53,310	[INFO]	/usr/local/lib/python3.11/site-packages/django/core/servers/basehttp.py(Line:212)	"GET /accounts/login/ HTTP/1.1" 302 0
2023-06-04 19:59:53,318	[INFO]	/usr/local/lib/python3.11/site-packages/django/core/servers/basehttp.py(Line:212)	"GET /diary-list HTTP/1.1" 200 3744
2023-06-04 19:59:53,328	[WARNING]	/usr/local/lib/python3.11/site-packages/django/core/servers/basehttp.py(Line:212)	"GET /static/js/bootstrap.bundle.min.js HTTP/1.1" 404 1837
2023-06-04 19:59:53,329	[WARNING]	/usr/local/lib/python3.11/site-packages/django/core/servers/basehttp.py(Line:212)	"GET /static/css/clean-blog.min.css HTTP/1.1" 404 1825
2023-06-04 19:59:59,654	[INFO]	/usr/local/lib/python3.11/site-packages/django/core/servers/basehttp.py(Line:212)	"GET /accounts/logout/ HTTP/1.1" 302 0
2023-06-04 19:59:59,665	[INFO]	/usr/local/lib/python3.11/site-packages/django/core/servers/basehttp.py(Line:212)	"GET /accounts/login/ HTTP/1.1" 200 4742
2023-06-04 19:59:59,674	[WARNING]	/usr/local/lib/python3.11/site-packages/django/core/servers/basehttp.py(Line:212)	"GET /static/js/bootstrap.bundle.min.js HTTP/1.1" 404 1837
2023-06-04 20:00:00,966	[INFO]	/usr/local/lib/python3.11/site-packages/django/core/servers/basehttp.py(Line:212)	"GET /accounts/login/ HTTP/1.1" 200 4347
2023-06-04 20:00:00,979	[WARNING]	/usr/local/lib/python3.11/site-packages/django/core/servers/basehttp.py(Line:212)	"GET /static/js/bootstrap.bundle.min.js HTTP/1.1" 404 1837
2023-06-04 20:00:08,607	[INFO]	/usr/local/lib/python3.11/site-packages/django/core/servers/basehttp.py(Line:212)	"POST /accounts/login/ HTTP/1.1" 302 0
2023-06-04 20:00:08,616	[INFO]	/usr/local/lib/python3.11/site-packages/django/core/servers/basehttp.py(Line:212)	"GET /diary-list HTTP/1.1" 200 4163
2023-06-04 20:00:08,629	[WARNING]	/usr/local/lib/python3.11/site-packages/django/core/servers/basehttp.py(Line:212)	"GET /static/css/clean-blog.min.css HTTP/1.1" 404 1825
2023-06-04 20:00:08,629	[WARNING]	/usr/local/lib/python3.11/site-packages/django/core/servers/basehttp.py(Line:212)	"GET /static/js/bootstrap.bundle.min.js HTTP/1.1" 404 1837
